<?xml version="1.0"?>
<robot xmlns:xacro="http://www.ros.org/wiki/xacro" name="self_balancing_ai">

<!--BASE WITH SUPPORT
<xacro:property name="inertia_base">
	<inertia ixx="0.0015930614" ixy="-0.00000211350543" ixz="-0.0000100387609" iyy="0.00171635411" iyz="0.00000206281250" izz="0.00115668591"/>
</xacro:property>
-->
<xacro:property name="inertia_base">
	<inertia ixx="0.000889344343" ixy="0.0000000487885241" ixz="-0.00000353505815" iyy="0.00148391703" iyz="0.000000418243917" izz="0.000753680226"/>
</xacro:property>

<xacro:property name="inertia_motor">
	<!--<inertia ixx="0.0000315494444" ixy="0.0" ixz="0.0" iyy="0.0000315494444" iyz="0.0" izz="0.00000842933333"/>-->
	<inertia ixx="0" ixy="0.0" ixz="0.0" iyy="0" iyz="0.0" izz="0.00000000000000000000001"/>
</xacro:property>

<xacro:property name="inertia_wheel">
	<inertia ixx="0" ixy="0.0" ixz="0.0" iyy="0" iyz="0.0" izz="0.00000000000000000000001"/>
	<!--<inertia ixx="0.0000" ixy="0.0" ixz="0.0" iyy="0.0000" iyz="0.0" izz="0.00002734375"/>-->
</xacro:property>

<xacro:property name="inertia_battery">
 <inertia ixx="0.0000345" ixy="0.0" ixz="0.0" iyy="0.000146625" iyz="0.0" izz="0.000167325"/>
</xacro:property>
  <material name="Blue">

    <color rgba="${255/255} ${108/255} ${10/255} 0.9"/>
  </material>

  <material name="White">
    <color rgba="${255/255} ${255/255} ${255/255} ${0.9}"/>
  </material>

  <material name="Black">
    <color rgba="${0/255} ${0/255} ${0/255} ${0.9}"/>
  </material>

  <link name="dummy_link">
    <visual>
      <geometry>
        <box size="0.001 0.001 0.001"/>
      </geometry>
      <origin rpy="0 0 0" xyz="0 0 0"/>
      <material name="White"/>
    </visual>
    <collision>
      <geometry>
        <box size="0.001 0.001 0.001"/>
      </geometry>
      <origin rpy="0 0 0" xyz="0 0 0"/>
    </collision>
    <inertial>
      <mass value="0.001"/>
      <inertia ixx="0.000000000001" ixy="0.0" ixz="0.0" iyy="0.00000000001" iyz="0.0" izz="0.00000000001"/>
    </inertial>
  </link>

  <joint name="dummy_link_base_segway" type="fixed">
    <parent link="dummy_link"/>
    <child link="base_segway"/>
    <origin rpy="0 0 0" xyz="0 0 0.0"/>
  </joint>


  <link name="base_segway">
    <visual>	
	<!--
      <geometry>
        <box size="0.15 0.06 0.17"/>
      </geometry>
	-->
      <geometry>
        <mesh filename="package://self_balancing_ai/mesh/base.stl"/>
      </geometry>
      <origin rpy="0 0 0" xyz="-0.105 -0.04 -0.12"/>
      <material name="White"/>
    </visual>
    <collision>
      <geometry>
        <box size="0.15 0.06 0.17"/>
      </geometry>
      <origin rpy="0 0 0" xyz="0 0 0"/>
    </collision>
    <inertial>
      <mass value="0.287"/>
     <xacro:insert_block name="inertia_base"/>
    </inertial>
  </link>


  <link name="battery">
    <visual>
      <geometry>
        <box size="0.09 0.04 0.02"/>
      </geometry>
      <origin rpy="0 0 0" xyz="0 0 0"/>
      <material name="Green"/>
    </visual>
    <collision>
      <geometry>
        <box size="0.09 0.04 0.02"/>
      </geometry>
      <origin rpy="0 0 0" xyz="0 0 0"/>
    </collision>
    <inertial>
      <mass value="0.2"/>
     <xacro:insert_block name="inertia_battery"/>
    </inertial>
  </link>

  <joint name="base_segway_battery" type="fixed">
    <parent link="base_segway"/>
    <child link="battery"/>
    <origin rpy="0 0 0" xyz="0 0 0.095"/>
  </joint>


  <link name="motor_l">
    <visual>
      <geometry>
        <cylinder radius="0.0125" length="0.07"/>
      </geometry>
      <origin rpy="0 1.5708 0" xyz="0 0 0"/>
      <material name="Black"/>
    </visual>
    <collision>
      <geometry>
        <cylinder radius="0.0125" length="0.07"/>
      </geometry>
      <origin rpy="0 1.5708 0" xyz="0 0 0"/>
    </collision>
    <inertial>
      <mass value="0.1"/>
     <xacro:insert_block name="inertia_motor"/>
    </inertial>
  </link>

  <joint name="base_segway_motorl" type="fixed">
    <parent link="base_segway"/>
    <child link="motor_l"/>
    <origin rpy="0 0 0" xyz="0.035 0 -0.1"/>
  </joint>


  <link name="motor_r">
    <visual>
      <geometry>
        <cylinder radius="0.0125" length="0.07"/>
      </geometry>
      <origin rpy="0 1.5708 0" xyz="0 0 0"/>
      <material name="Black"/>
    </visual>
    <collision>
      <geometry>
        <cylinder radius="0.0125" length="0.07"/>
      </geometry>
      <origin rpy="0 1.5708 0" xyz="0 0 0"/>
    </collision>
    <inertial>
      <mass value="0.1"/>
     <xacro:insert_block name="inertia_motor"/>
    </inertial>
  </link>

  <joint name="base_segway_motorr" type="fixed">
    <parent link="base_segway"/>
    <child link="motor_r"/>
    <origin rpy="0 0 0" xyz="-0.035 0 -0.1"/>
  </joint>


  <link name="wheel_l">
    <visual>
      <geometry>
	      <cylinder radius="0.0325" length="0.025"/>
	      <!--<cylinder radius="0.04" length="0.025"/>-->
      </geometry>
      <origin rpy="0 1.5708 0" xyz="0 0 0"/>
      <material name="Black"/>
    </visual>
    <collision>
      <geometry>
	      <cylinder radius="0.0325" length="0.025"/>
	      <!--<cylinder radius="0.04" length="0.025"/>-->
      </geometry>
      <origin rpy="0 1.5708 0" xyz="0 0 0"/>
    </collision>
    <inertial>
      <mass value="0.035"/>
     <xacro:insert_block name="inertia_wheel"/>
    </inertial>
  </link>

 <joint name="motor_l_wheell" type="continuous">
    <parent link="motor_l"/>
    <child link="wheel_l"/>
    <origin rpy="0 0 0" xyz="0.07 0 0"/>
    <!--<dynamics damping="5.61e-32" friction="0.08"/>-->
    <limit effort="0.3" velocity="1.0"  />
  </joint>

  <link name="wheel_r">
	  <visual>
      <geometry>
	      <cylinder radius="0.0325" length="0.025"/>
	      <!--<cylinder radius="0.04" length="0.025"/>-->
      </geometry>
      <origin rpy="0 -1.5708 0" xyz="0 0 0"/>
      <material name="Black"/>
    </visual>
    <collision>
      <geometry>
	      <cylinder radius="0.0325" length="0.025"/>
	      <!--<cylinder radius="0.04" length="0.025"/>-->
      </geometry>
      <origin rpy="0 -1.5708 0" xyz="0 0 0"/>
    </collision>
    <inertial>
      <mass value="0.035"/>
     <xacro:insert_block name="inertia_wheel"/>
    </inertial>
  </link>

  <joint name="motor_r_wheelr" type="continuous">
    <parent link="motor_r"/>
    <child link="wheel_r"/>
    <origin rpy="0 0 0" xyz="-0.07 0 0"/>
    <!--<dynamics damping="5.61e-32" friction="0.08"/>-->
    <limit effort="0.3" velocity="1.0"  />
  </joint>



<!-- TRANSMISSION -->

  <transmission name="motor_l_wheell_trans">
    <type>transmission_interface/SimpleTransmission</type>
    <joint name="motor_l_wheell">
      <hardwareInterface>hardware_interface/EffortJointInterface</hardwareInterface>
    </joint>
    <actuator name="motor_l_wheell_motor">
      <hardwareInterface>hardware_interface/EffortJointInterface</hardwareInterface>
      <mechanicalReduction>1</mechanicalReduction>
    </actuator>
  </transmission>

  <transmission name="motor_r_wheelr_trans">
    <type>transmission_interface/SimpleTransmission</type>
    <joint name="motor_r_wheelr">
      <hardwareInterface>hardware_interface/EffortJointInterface</hardwareInterface>
    </joint>
    <actuator name="motor_r_segway_wheelr_motor">
      <hardwareInterface>hardware_interface/EffortJointInterface</hardwareInterface>
      <mechanicalReduction>1</mechanicalReduction>
    </actuator>
  </transmission>

<gazebo reference="base_segway">
  <material>Gazebo/White</material>
  <mu1>1e100</mu1>
  <mu2>1e100</mu2>
  <kp>1e-15</kp>
  <kd>1e-13</kd>
    <maxVel>0.0</maxVel>
    <selfCollide>true</selfCollide>
    <static>true</static>
    <turnGravityOff>false</turnGravityOff>
</gazebo>

<gazebo reference="battery">
  <material>Gazebo/Green</material>
  <mu1>1e100</mu1>
  <mu2>1e100</mu2>
  <kp>1e-15</kp>
  <kd>1e13</kd>
    <maxVel>0.0</maxVel>
    <selfCollide>true</selfCollide>
    <static>true</static>
    <turnGravityOff>false</turnGravityOff>
</gazebo>

<gazebo reference="motor_r">
  <material>Gazebo/White</material>
  <mu1>1e100</mu1>
  <mu2>1e100</mu2>
  <kp>1e-15</kp>
  <kd>1e13</kd>
    <maxVel>0.0</maxVel>
    <selfCollide>true</selfCollide>
    <static>true</static>
    <turnGravityOff>false</turnGravityOff>
</gazebo>

<gazebo reference="motor_l">
  <material>Gazebo/White</material>
  <mu1>1e100</mu1>
  <mu2>1e100</mu2>
  <kp>1e-15</kp>
  <kd>1e13</kd>
    <maxVel>0.0</maxVel>
    <selfCollide>true</selfCollide>
    <static>true</static>
    <turnGravityOff>false</turnGravityOff>
</gazebo>

<gazebo reference="wheel_l">
  <material>Gazebo/Black</material>
    <kp>1000000.0</kp>
    <kd>100.0</kd>
	  <mu1>0.8</mu1>
	  <mu2>0.8</mu2>

  <maxVel>0</maxVel>
  <minDepth>0.000</minDepth>
    <selfCollide>true</selfCollide>
    <static>false</static>
    <turnGravityOff>false</turnGravityOff>
</gazebo>

<gazebo reference="wheel_r">
  <material>Gazebo/Black</material>
    <kp>1000000.0</kp>
    <kd>100.0</kd>
	  <mu1>0.8</mu1>
	  <mu2>0.8</mu2>


  <maxVel>0</maxVel>
  <minDepth>0.000</minDepth>
    <selfCollide>true</selfCollide>
    <static>false</static>
    <turnGravityOff>false</turnGravityOff>
</gazebo>


  <gazebo>
      <plugin name="gazebo_ros_control" filename="libgazebo_ros_control.so">
      <robotNamespace>/self_balancing_ai</robotNamespace>
    </plugin>


		<plugin name="imu_plugin" filename="libgazebo_ros_imu.so">
			<alwaysOn>true</alwaysOn>
			<bodyName>base_segway</bodyName>
			<topicName>imu</topicName>
			<serviceName>imu_service</serviceName>
			<gaussianNoise>0.0</gaussianNoise>
			<rpyOffsets>0 0 0</rpyOffsets>
			<accelDrift>0.05 0.05 0.05</accelDrift>
			<accelGaussianNoise>0.035 0.035 0.03</accelGaussianNoise>
			<rateDrift>0.0 0.0 0.0</rateDrift>
        	<rateGaussianNoise>0.00 0.00 0.00</rateGaussianNoise>
        	<headingDrift>0.0</headingDrift>
        	<headingGaussianNoise>0.00</headingGaussianNoise>
			<updateRate>00</updateRate>
		</plugin>

  </gazebo>

  


</robot>



